Workbook
Name Slicer_gender: #N/A
Name Slicer_platform_usage: #N/A

Sheet Teen_Mental_Health_Dataset
A1: age | B1: gender | C1: daily_social_media_hours | D1: platform_usage | E1: sleep_hours | F1: screen_time_before_sleep | G1: academic_performance | H1: physical_activity | I1: social_interaction_level | J1: stress_level | K1: anxiety_level | L1: addiction_level | M1: depression_label
A2: 14 | B2: male | C2: 7.9 | D2: Instagram | E2: 7.4 | F2: 2.9 | G2: 3.01 | H2: 1.5 | I2: low | J2: 2 | K2: 2 | L2: 1 | M2: 0
A3: 19 | B3: female | C3: 1.9 | D3: TikTok | E3: 8 | F3: 2.9 | G3: 3.22 | H3: 0.8 | I3: high | J3: 8 | K3: 1 | L3: 10 | M3: 0
A4: 17 | B4: female | C4: 1.3 | D4: Instagram | E4: 7.6 | F4: 0.5 | G4: 3.92 | H4: 0 | I4: high | J4: 2 | K4: 4 | L4: 2 | M4: 0
A5: 15 | B5: male | C5: 7.4 | D5: TikTok | E5: 6.9 | F5: 1.6 | G5: 3.48 | H5: 0.8 | I5: medium | J5: 1 | K5: 7 | L5: 9 | M5: 0
A6: 15 | B6: female | C6: 4.7 | D6: Both | E6: 4.9 | F6: 3 | G6: 2.37 | H6: 1.4 | I6: medium | J6: 3 | K6: 5 | L6: 2 | M6: 0
A7: 19 | B7: female | C7: 7.4 | D7: Both | E7: 4.4 | F7: 2.4 | G7: 2.63 | H7: 0.6 | I7: high | J7: 3 | K7: 5 | L7: 7 | M7: 0
A8: 18 | B8: female | C8: 2.5 | D8: Instagram | E8: 6.4 | F8: 2.4 | G8: 2.63 | H8: 0.7 | I8: low | J8: 2 | K8: 2 | L8: 5 | M8: 0
A9: 16 | B9: male | C9: 4 | D9: Both | E9: 4.2 | F9: 0.5 | G9: 2.4 | H9: 1.3 | I9: low | J9: 6 | K9: 10 | L9: 5 | M9: 0
A10: 19 | B10: female | C10: 3.3 | D10: TikTok | E10: 5 | F10: 2.1 | G10: 2.04 | H10: 0.9 | I10: high | J10: 1 | K10: 10 | L10: 9 | M10: 0
A11: 15 | B11: male | C11: 1.9 | D11: TikTok | E11: 4.9 | F11: 1.5 | G11: 3.77 | H11: 1.1 | I11: high | J11: 1 | K11: 1 | L11: 4 | M11: 0
A12: 16 | B12: male | C12: 7.2 | D12: Both | E12: 5.8 | F12: 2.9 | G12: 3.16 | H12: 1.2 | I12: medium | J12: 5 | K12: 8 | L12: 9 | M12: 0
A13: 13 | B13: male | C13: 4.9 | D13: Instagram | E13: 4.7 | F13: 2.5 | G13: 3.92 | H13: 1.2 | I13: low | J13: 1 | K13: 10 | L13: 8 | M13: 0
... A1201: 16 | B1201: female | C1201: 4.7 | D1201: TikTok | E1201: 6.5 | F1201: 1 | G1201: 2.91 | H1201: 0.9 | I1201: medium | J1201: 5 | K1201: 7 | L1201: 3 | M1201: 0

Sheet Working sheet
A1: age | B1: gender | C1: daily_social_media_hours | D1: platform_usage | E1: sleep_hours | F1: screen_time_before_sleep | G1: academic_performance | H1: physical_activity | I1: social_interaction_level | J1: stress_level | K1: anxiety_level | L1: addiction_level | M1: depression_label
A2: 14 | B2: male | C2: 7.9 | D2: Instagram | E2: 7.4 | F2: 2.9 | G2: 3.01 | H2: 1.5 | I2: low | J2: 2 | K2: 2 | L2: 1 | M2: 0
A3: 19 | B3: female | C3: 1.9 | D3: TikTok | E3: 8 | F3: 2.9 | G3: 3.22 | H3: 0.8 | I3: high | J3: 8 | K3: 1 | L3: 10 | M3: 0
A4: 17 | B4: female | C4: 1.3 | D4: Instagram | E4: 7.6 | F4: 0.5 | G4: 3.92 | H4: 0 | I4: high | J4: 2 | K4: 4 | L4: 2 | M4: 0
A5: 15 | B5: male | C5: 7.4 | D5: TikTok | E5: 6.9 | F5: 1.6 | G5: 3.48 | H5: 0.8 | I5: medium | J5: 1 | K5: 7 | L5: 9 | M5: 0
A6: 15 | B6: female | C6: 4.7 | D6: Both | E6: 4.9 | F6: 3 | G6: 2.37 | H6: 1.4 | I6: medium | J6: 3 | K6: 5 | L6: 2 | M6: 0
A7: 19 | B7: female | C7: 7.4 | D7: Both | E7: 4.4 | F7: 2.4 | G7: 2.63 | H7: 0.6 | I7: high | J7: 3 | K7: 5 | L7: 7 | M7: 0
A8: 18 | B8: female | C8: 2.5 | D8: Instagram | E8: 6.4 | F8: 2.4 | G8: 2.63 | H8: 0.7 | I8: low | J8: 2 | K8: 2 | L8: 5 | M8: 0
A9: 16 | B9: male | C9: 4 | D9: Both | E9: 4.2 | F9: 0.5 | G9: 2.4 | H9: 1.3 | I9: low | J9: 6 | K9: 10 | L9: 5 | M9: 0
A10: 19 | B10: female | C10: 3.3 | D10: TikTok | E10: 5 | F10: 2.1 | G10: 2.04 | H10: 0.9 | I10: high | J10: 1 | K10: 10 | L10: 9 | M10: 0
A11: 15 | B11: male | C11: 1.9 | D11: TikTok | E11: 4.9 | F11: 1.5 | G11: 3.77 | H11: 1.1 | I11: high | J11: 1 | K11: 1 | L11: 4 | M11: 0
A12: 16 | B12: male | C12: 7.2 | D12: Both | E12: 5.8 | F12: 2.9 | G12: 3.16 | H12: 1.2 | I12: medium | J12: 5 | K12: 8 | L12: 9 | M12: 0
A13: 13 | B13: male | C13: 4.9 | D13: Instagram | E13: 4.7 | F13: 2.5 | G13: 3.92 | H13: 1.2 | I13: low | J13: 1 | K13: 10 | L13: 8 | M13: 0
... A1201: 16 | B1201: female | C1201: 4.7 | D1201: TikTok | E1201: 6.5 | F1201: 1 | G1201: 2.91 | H1201: 0.9 | I1201: medium | J1201: 5 | K1201: 7 | L1201: 3 | M1201: 0

Sheet Analis Data
A1: 1 | B1: Total Responden | E1: =COUNT('Working sheet'!A2:A1201) -> 1200
A2: 2 | B2: Terdepresi | E2: =COUNTIF(Teen_Mental_Health_Dataset!M2:M1201,1) -> 31
A3: 3 | B3: Rata-rata medsos | E3: =AVERAGE('Working sheet'!C2:C1201) -> 4.5366667
A4: 4 | B4: Rata-rata tidur | E4: =AVERAGE('Working sheet'!E2:E1201) -> 6.4494167
A5: 5 | B5: Rata-rata stress | E5: =AVERAGE('Working sheet'!J2:J1201) -> 5.4458333
A6: 6 | B6: Rata-raya Kecemasan | E6: =AVERAGE('Working sheet'!K2:K1201) -> 5.6366667
A7: 7 | B7: Distribusi Gender | E7: =COUNTIF('Working sheet'!B2:B1201,"female") -> 585 | F7: female | G7: =COUNTIF('Working sheet'!B2:B1201,"male") -> 615 | H7: male
A8: 8 | B8: Pengguna Platform | E8: =COUNTIF('Working sheet'!D2:D1201,"Instagram") -> 411 | F8: =COUNTIF('Working sheet'!D2:D1201,"Tiktok") -> 398 | G8: Intagram Tiktok | H8: =COUNTIF('Working sheet'!D2:D1201,"Both") -> 391 | I8: Both
A9: 9 | B9: Rata-rata Jam Medsos (Depresi vs tidak) | C9: Depresi - Faktor Resiko Utama | E9: =AVERAGEIFS('Working sheet'!C2:C1201,'Working sheet'!M2:M1201,0) -> 4.4787853 | F9: rata medsos tdk depresi | G9: =AVERAGEIFS('Working sheet'!C2:C1201,'Working sheet'!M2:M1201,1) -> 6.7193548 | H9: rata medsos depresi
A10: 10 | B10: Rata-rata jam Tidur (Depresi vs tidak) | C10: Depresi - Faktor Resiko Utama | E10: =AVERAGEIFS('Working sheet'!E2:E1201,'Working sheet'!M2:M1201,0) -> 6.4941831 | F10: rata tidur tidak depresi | G10: =AVERAGEIFS('Working sheet'!E2:E1201,'Working sheet'!M2:M1201,1) -> 4.7612903 | H10: raa tidur depresi
A11: 11 | B11: Depresi Kelompok Jam Tidur | C11: Korelasi Jam Tidur & Medsos Terhadap Depresi (%)
A12: 12 | B12: Depresi Kelompok Jam Medsos | C12: Korelasi Jam Tidur & Medsos Terhadap Depresi (%)
A13: 13 | B13: Level Stress & Kecemasan | C13: Level Stress & Kecemasan pada remaja depresi vs tidak | E13: Stres (depresi vs tidak) | F13: =AVERAGEIFS('Working sheet'!J2:J1201,'Working sheet'!M2:M1201,1) -> 8.483871 | G13: =AVERAGEIFS('Working sheet'!J2:J1201,'Working sheet'!M2:M1201,0) -> 5.3652695 | H13: Kecemasan (depresi vs tidak depresi) | I13: =AVERAGEIFS('Working sheet'!K2:K1201,'Working sheet'!M2:M1201,1) -> 8.6129032 | J13: =AVERAGEIFS('Working sheet'!K2:K1201,'Working sheet'!M2:M1201,0) -> 5.5577417
A14: 14 | B14: Rata-rata Indikator Mental Per Usia
A15: 15 | B15: Korelasi Variabel dengan Depresi
A16: 16 | B16: Depresi per platform | C16: Depresi berdasarkan platform & gender | E16: Instagram | F16: =COUNTIFS('Working sheet'!M2:M1201,1,'Working sheet'!D2:D1201,"Instagram") -> 10 | G16: Tiktok | H16: =COUNTIFS('Working sheet'!M2:M1201,1,'Working sheet'!D2:D1201,"Tiktok") -> 12 | I16: Both | J16: =COUNTIFS('Working sheet'!M2:M1201,1,'Working sheet'!D2:D1201,"Both") -> 9
A17: 17 | B17: Depresi per gender | C17: Depresi berdasarkan platform & gender | E17: female | F17: =COUNTIFS('Working sheet'!M2:M1201,1,'Working sheet'!B2:B1201,"female") -> 17 | G17: male | H17: =COUNTIFS('Working sheet'!M2:M1201,1,'Working sheet'!B2:B1201,"male") -> 14
G20: Stress | H20: Anxity

Sheet Pivot Table
A1: 7 | B1: Distribusi Gender | E1: 585 | F1: female | G1: 615 | H1: male
B2: Row Labels | C2: Count of platform_usage
B3: female | C3: 585
B4: male | C4: 615
B5: Grand Total | C5: 1200
A8: 8 | B8: Pengguna Platform | E8: 411 | F8: 398 | G8: Intagram Tiktok | H8: 391 | I8: Both
B9: Row Labels | C9: Count of gender
B10: Both | C10: 391
B11: Instagram | C11: 411
B12: TikTok | C12: 398
B13: Grand Total | C13: 1200
A15: 9 | B15: Rata-rata Jam Medsos (Depresi vs tidak) | C15: Depresi - Faktor Resiko Utama | E15: 4.4787853 | F15: rata medsos tdk depresi | G15: 6.7193548 | H15: rata medsos depresi
B16: Row Labels | C16: Average of daily_social_media_hours | D16: Average of sleep_hours
B17: 0 | C17: 4.4787853 | D17: 6.4941831
B18: Grand Total | C18: 4.4787853 | D18: 6.4941831
A21: 10 | B21: Rata-rata jam Tidur (Depresi vs tidak) | C21: Depresi - Faktor Resiko Utama | E21: 6.4941831 | F21: rata tidur tidak depresi | G21: 4.7612903 | H21: raa tidur depresi
B22: Row Labels | C22: Average of daily_social_media_hours | D22: Average of sleep_hours
B23: 0 | C23: 4.4787853 | D23: 6.4941831
B24: 1 | C24: 6.7193548 | D24: 4.7612903
B25: Grand Total | C25: 4.5366667 | D25: 6.4494167
A28: 12 | B28: Depresi Kelompok Jam Medsos | C28: Korelasi Jam Tidur & Medsos Terhadap Depresi (%) | J28: 11 | K28: Depresi Kelompok Jam Tidur | L28: Korelasi Jam Tidur & Medsos Terhadap Depresi (%)
B29: Row Labels | C29: Sum of depression_label | F29: Row Labels | G29: Sum of depression_label | H29: <5 | I29: 22 | J29: Row Labels | K29: Sum of depression_label | L29: 1 - 7 jam 16 orang | M29: Row Labels | N29: Sum of depression_label | O29: 7-9 jam 15 orang
B30: 4 | C30: 0 | F30: 5.1 | G30: 0 | H30: 5-8 jam | I30: 9 | J30: 1 | K30: 0 | M30: 7.1 | N30: 0
B31: 4.1 | C31: 3 | F31: 5.2 | G31: 1 | J31: 1.1 | K31: 0 | M31: 7.2 | N31: 2
B32: 4.2 | C32: 5 | F32: 5.3 | G32: 1 | J32: 1.2 | K32: 0 | M32: 7.3 | N32: 1
B33: 4.3 | C33: 2 | F33: 5.4 | G33: 1 | J33: 1.3 | K33: 0 | M33: 7.4 | N33: 2
B34: 4.4 | C34: 3 | F34: 5.5 | G34: 1 | J34: 1.4 | K34: 0 | M34: 7.5 | N34: 2
B35: 4.5 | C35: 1 | F35: 5.6 | G35: 2 | J35: 1.5 | K35: 0 | M35: 7.6 | N35: 0
B36: 4.6 | C36: 2 | F36: 5.7 | G36: 2 | J36: 1.6 | K36: 0 | M36: 7.7 | N36: 2
B37: 4.7 | C37: 2 | F37: 5.8 | G37: 1 | J37: 1.7 | K37: 0 | M37: 7.8 | N37: 4
B38: 4.8 | C38: 2 | F38: 5.9 | G38: 0 | J38: 1.8 | K38: 0 | M38: 7.9 | N38: 0
B39: 4.9 | C39: 0 | F39: 6 | G39: 0 | J39: 1.9 | K39: 0 | M39: 8 | N39: 2
B40: 5 | C40: 2 | F40: 6.1 | G40: 0 | J40: 2 | K40: 0 | M40: Grand Total | N40: 15
B41: Grand Total | C41: 22 | F41: 6.2 | G41: 0 | J41: 2.1 | K41: 0
B42: Jam | C42: Jumlah | F42: 6.3 | G42: 0 | J42: 2.2 | K42: 0 | M42: < 7 Jam | N42: 16
B43: <5 Jam | C43: 22 | F43: 6.4 | G43: 0 | J43: 2.3 | K43: 0 | M43: 7 - 9 Jam | N43: 15
B44: 5 - 9 Jam | C44: 9 | F44: 6.5 | G44: 0 | J44: 2.4 | K44: 0
F45: 6.6 | G45: 0 | J45: 2.5 | K45: 0
F46: 6.7 | G46: 0 | J46: 2.6 | K46: 0
F47: 6.8 | G47: 0 | J47: 2.7 | K47: 0
...

Sheet Dashboard
